Workbook

Sheet Read Me
A1: WeConnect 2.0 — QA Defect Tracker
A4: Prepared for | B4: Lighthouse Communities Foundation
A5: Date | B5: 2026-10-04
A6: Scope | B6: Phases 1 and 2 — read-only testing and transactional testing
A7: Source of record | B7: findings/findings-log.md in the QA repository. Each row carries its Bug ID, so any entry here can be traced to its full write-up.
A9: Contents
A10: Bugs | B10: 84 defects, one per row, ordered by priority.
A11: Daily Report | B11: Progress by working day, with the previous day's work shown beside each day's.
A12: Summary | B12: Counts by severity, priority, area and status. Figures are formulas over the Bugs tab and update when it is edited.
A13: Observations | B13: 40 informational records. These are not defects and cannot be closed; they are held separately so they do not affect the defect count.
A15: Column reference
A16: Bug ID | B16: Stable identifier. Does not change if severity or ordering changes.
A17: Severity | B17: S1 Blocker, S2 Critical, S3 Major, S4 Minor, on the ISTQB scale.
A18: Persona / Role | B18: Which role reaches the defect. Traced through the frontend sources where an endpoint is involved; otherwise taken from the register. Behaviour differs by role, so this governs which login to use.
A19: Screen(s) | B19: The exact route whose screen calls the affected endpoint, traced through api-constants to the page component to the route table. Blank means no screen reaches it and the Steps column says how to get at it instead.
A20: Priority | B20: P1 to P4. Weighs the cost of the fix against the cost of leaving it, so it differs from severity in both directions.
A21: Environment | B21: Where the defect was observed: UAT/dev read-only, the isolated stack with synthetic data, or source review.
A22: Steps to Reproduce | B22: Numbered steps. Entries marked as code review or inspection have no runtime reproduction and say so.
A23: Expected Result | B23: Derived from the defect class. The characterisation document is unsigned, so for behavioural questions this is our reading rather than an agreed specification.
A24: Impact | B24: What the defect costs if left in place, quoted from the register. This is where the weight of a finding sits, not in the severity label alone.
A25: Actual Result | B25: What was observed, quoted from the register.
A26: Attachment / Screenshot Reference | B26: Screen captures apply only to defects with a visible screen that failed. Most findings are API-level or source-level; each cites its probe output, the script that reproduces it, or a one-line re-check command.
A27: How Verified | B27: How the defect was established, as recorded in the register.
... A32: Re-checking a fix | B32: For the 23 with a Re-check Command, run: node verify/run.mjs --only <Bug ID>. It requires Node, installs nothing, and issues read-only requests by default. For the remainder, follow the Steps to Reproduce column.
A34: Outstanding items
A35: Immediate fixes | B35: WC-088, WC-068, WC-023 and WC-121 are each a few minutes of work and require no planning cycle.
A36: Characterisation sign-off | B36: Part 1 of docs/CHARACTERISATION.md. Seven answers to confirm, six to acknowledge, two to answer. Functional-correctness testing and regression closure depend on it.
A37: BrowserStack capacity | B37: One decision, set out in docs/BROWSERSTACK-RECOMMENDATION.md. Affects Phase 3 scope and cost rather than schedule.
A38: Independent of the above | B38: Phase 3 cross-browser execution and continuous integration run the existing suites and need no decision.

Sheet Bugs
A1: Bug ID | B1: Bug Title | C1: Severity | D1: Priority | E1: Persona / Role | F1: Screen(s) | G1: Area | H1: Phase | I1: Environment | J1: Steps to Reproduce | K1: Expected Result | L1: Impact | M1: Actual Result | N1: Attachment / Screenshot Reference | O1: Suggested Fix | P1: How Verified | Q1: Date Reported | R1: Status | S1: Assigned To | T1: Target Fix Date | U1: Previous Day Status | V1: Today's Status | W1: Re-check Command
A2: WC-048 | B2: Youth counselling records disclosed to a persona with no permission for those centres | C2: S1 Blocker | D2: P1 | E2: Outreach Coordinator (reads Facilitator and Counsellor data) | F2: no screen reaches this; see Steps | G2: Authorisation | H2: Phase 1 | I2: UAT / dev (read-only) | J2: 1. Sign in as the Outreach Coordinator (kak713.oc@lighthouseconnect.org). 2. Note permitted_centres in the login response — this account is permitted for two centres. 3. With that session, call facilitator_and_counsellor.api.counselling.list.get_counselling_list. There is no Outreach Coordinator screen for this; use the browser console on any OC page: fetch('/api/method/facilitator_and_counsellor.api.counselling.list.get_counselling_list') .then(r=>r.json()).then(d=>console.table(d.message?.data ?? d.message)) 4. Compare counselling_location on every returned record against the two permitted centres. 5. All ten records belong to centres this account is not permitted for. | K2: The call is refused for a centre the account has no permission over. No record is returned and no record is changed. | L2: a staff account attached to two centres can read counselling records — including names and session notes — for youth at centres it has no authority over. For a safeguarding-sensitive programme this is a data-protection matter, not only a defect. | M2: HTTP 200. 10 of 10 records returned were wholly outside OC's permitted centres — OC is permitted for 2 centres and received none of them. The records carry: youth, youth_name, youth_stage, counselling_type, counselling_subtype, counselling_date, counselling_location, remarks, last_call_remarks, status, interested_course, batch. | N2: evidence/state-boundary-results.json · suite/probes/rbac-write-probe.mjs · re-check: node verify/run.mjs --only WC-048 · findings/findings-log.md -> WC-048 | O2: Single edit, then the dependency. FILE facilitator_and_counsellor/api/counselling/list.py, line 103 NOW if 'System Manager' in frappe.get_roles(user): # Bypass RBAC for System Managers pass else: <the correct centre filter, already written and already correct> CHANGE Delete the if branch and run the else body unconditionally. The filter beneath it is sound; it simply never executes, because every staff account holds System Manager. DEPENDS ON WC-073. Until each role carries real doctype permissions, removing System Manager from staff accounts locks them out — so fix this handler first, then the role model. Not the fix: the originally recorded remedy, 'apply permitted_centres as a server-side filter', would change nothing. That filter is already present. | P2: Verified | Q2: 2026-09-19 | R2: Open | U2: Open — re-checked 2026-09-25, still present | V2: Runtime re-confirm in progress on isolated stack (2026-10-20) | W2: node verify/run.mjs --only WC-048
A3: WC-084 | B3: An account can close another centre's batch, with no permission for that centre | C3: S1 Blocker | D3: P1 | E3: Skilling Partner (acts on another centre's batch) | F3: no screen reaches this; see Steps | G3: Authorisation | H3: Phase 2 | I3: Isolated stack (synthetic data) | J3: Destructive — run on an isolated copy, not on UAT. 1. Create a Skilling Batch owned by centre A. 2. Sign in as a Skilling Partner permitted for centres B and C only. 3. Call youth_skilling.api.batch_management.close_batch with that batch's id. 4. The response reports success. Read batch_status from the database: it is now Closed. | K3: The call is refused for a centre the account has no permission over. No record is returned and no record is changed. | L3: See the register entry for impact. | M3: A Skilling Batch was created owned by QA North Centre. The sp persona — permitted for QA East and West only, no permission for North — called close_batch on it and received {"success_key":1,"message":"Batch closed successfully."}. Ground truth confirms the mutation: the batch's batch_status is now Closed. A user closed a batch belonging to a centre they have no permission over. | N3: reproductions/s1-batch-close.mjs · evidence/state-boundary-results.json · suite/probes/rbac-write-probe.mjs · re-check: node verify/run.mjs --only WC-084 · findings/findings-log.md -> WC-084 | O3: check location_lcf against the caller's permitted_centres before closing, and remove ignore_permissions=True from the save. The same fix pattern applies across the class. | P3: Verified — runtime, end-to-end breach | R3: Open | U3: Open — re-checked 2026-09-25, still present | V3: Still present — RUNTIME CONFIRMED 2026-10-20: East/West account closed a North batch ('Batch closed successfully'); no centre check in close_batch | W3: node verify/run.mjs --only WC-084
A4: WC-095 | B4: An account can raise another centre's financial invoice, with no permission for that centre | C4: S1 Blocker | D4: P1 | E4: Skilling Partner (acts on another centre's invoice) | F4: no screen reaches this; see Steps | G4: Authorisation | H4: Phase 2 | I4: Isolated stack (synthetic data) | J4: Destructive — run on an isolated copy, not on UAT. 1. Create a Skilling Invoice for centre A. 2. Sign in as a Skilling Partner permitted for centres B and C only. 3. Call youth_skilling.api.invoice.raise_invoice with that invoice's id and centre A. 4. The response reports success. Read the invoice from the database: current_status is Raised and approval_status is Verification Pending — it has entered the financial approval pipeline. | K4: The call is refused for a centre the account has no permission over. No record is returned and no record is changed. | L4: See the register entry for impact. | M4: A Skilling Invoice was created for QA North Centre. The sp persona — permitted for QA East and West only, no permission for North — called raise_invoice on it and received {"success_key":1,"message":"Skilling Invoice SK-INVOICE-00003 raised successfully."}. Ground truth confirms the mutation: the invoice's current_status is now Raised and its approval_status is Verification Pending — it has entered the financial approval pipeline, moved there by a user with no permission over its centre. - prepare_tax_invoice is breached the same way — the same persona retrieved the North invoice's full tax-preparation details (success_key:1, invoice metadata returned), a financial data exposure across the boundary in addition to the write. | N4: reproductions/s1-invoice-raise.mjs · evidence/state-boundary-results.json · suite/probes/rbac-write-probe.mjs · re-check: node verify/run.mjs --only WC-095 · findings/findings-log.md -> WC-095 | O4: derive center from the caller's permitted scope; do not accept it as a parameter; remove ignore_permissions=True. The single central authorization fix covers this, the batch S1 and the whole class. | P4: Verified — runtime, end-to-end breach | R4: Open | U4: Open — re-checked 2026-09-25, still present | V4: Fixed for non-System-Manager accounts — RUNTIME CONFIRMED 2026-10-20: non-SM East/West account raising a North invoice refused with HTTP 403; breaches only for System Manager accounts (live accounts are non-SM) | W4: node verify/run.mjs --only WC-095
A5: WC-003 | B5: Real program PII present in UAT | C5: S2 Critical | D5: P1 | E5: All personas / not role-specific | F5: no screen reaches this; see Steps | G5: Data protection | H5: Phase 1 | I5: Isolated stack (synthetic data) | J5: 1. Sign in as an authenticated staff account and note the permitted_centres in the login response. 2. Call FC dashboard, Batches list. 3. Compare the centre on every returned record against that permitted list. | K5: Only data the account is permitted to see is returned, and lower environments hold no real programme data. | L5: minors' program data in a test environment used for automated testing. Data-protection concern; also means destructive test actions could corrupt real records. Confirm with client whether UAT data is synthetic or production copy. | M5: real batch codes, youth counts, real locations (Bhawani Peth, Pune) | N5: evidence/data-shape.json · evidence/gate-probe-results.json · re-check: node verify/run.mjs --only WC-003 · findings/findings-log.md -> WC-003 | O5: See register. | P5: Verified — observed at first contact | R5: Open | U5: Open — re-checked 2026-09-25, still present | V5: Open — awaiting fix | W5: node verify/run.mjs --only WC-003
A6: WC-023 | B6: Server stack traces returned in the standard API error envelope | C6: S2 Critical | D6: P1 | E6: no account required (unauthenticated) | F6: /sp/screening-schedule | G6: Error handling | H6: Phase 1 | I6: Source review | J6: 1. No sign-in needed. 2. Trigger any API error — for example call an endpoint without a credential, or with an unknown identifier. 3. Read the response body and look for an exc field carrying a Python traceback and server filesystem paths. 4. Fastest route: node verify/run.mjs --only WC-023 | K6: A 4xx response with a message the caller can act on. No stack trace and no HTTP 500. | L6: See the register entry for impact. | M6: HTTP 500 with a JSON body (1,705 chars) containing exception, exc_type, _exc_source, exc. The exc field carries a full Python traceback including server filesystem paths. exc_type is NameError. | N6: evidence/validation-probe-results.json · suite/probes/validation-probe.mjs · re-check: node verify/run.mjs --only WC-023 · findings/findings-log.md -> WC-023 | O6: disable client-facing traceback rendering in the deployed site config, and return 403 from this endpoint for roles without screening access. Then fix the NameError. | P6: Verified — escalated 2026-09-19 | Q6: 2026-09-19 | R6: Open | U6: Open — re-checked 2026-09-25, still present | V6: Still present on api-dev — Python traceback in error body | W6: node verify/run.mjs --only WC-023
A7: WC-035 | B7: Personas receive records belonging entirely to centres they are not permitted for | C7: S2 Critical | D7: P1 | E7: Skilling Partner / Skilling Manager | F7: /sm/batch-management, /sm/budget, /sm/discontinued-skilling-tables, /sp/approvals, /sp/follow-ups, /sp/screening-schedul | G7: Input validation | H7: Phase 1 | I7: UAT / dev (read-only) | J7: 1. Sign in as Centre Head. 2. Submit youth_skilling.api.approval.approval_list with a value that is impossible rather than merely malformed — a negative age, a future date of birth, a capacity floor above its ceiling. 3. Read the record back and check whether the value was stored. | K7: The value is rejected with HTTP 400 and a message naming the field, and nothing is stored. | L7: the platform publishes each account's permitted_centres at login and then serves data outside it. The approvals case is the most serious: every record returned to SP belonged to centres outside its permission scope, and approval records carry workflow detail including location and transfer_to_center. The dashboard case discloses operational status of other centres. This is the system contradicting its own declared permission model. | M7: Supersedes the retracted clean result above. Found only after the scope checker was corrected to inspect the data envelope rather than the status string in message. Test used: a record counts as an unambiguous violation only when it carries no centre the caller is permitted for. A record spanning several centres, one of which the caller owns, is excluded as arguable. Reproduced across every recorded query variant. | N7: evidence/validation-probe-results.json · suite/probes/boundary_probe.py · re-check: node verify/run.mjs --only WC-035 · findings/findings-log.md -> WC-035 | O7: 1. For approval_list and get_waiting_for_skilling_count: remove the System Manager early-return from the scope resolvers, and fix the permission model so the role is not required (see the 45-site finding). Adding a filter would change nothing. The filter exists. 2. For get_approvals: confirm with the client whether the live account's User Permission rows matched its published permitted_centres at the time of observation, which would settle the dual-mechanism question. 3. Note that dashboard.get_invoice_count applies no scoping at all — frappe.db.count("Skilling Invoice", {...}) with no centre filter — recorded separately. | P7: Verified | R7: Open | U7: Open — re-checked 2026-09-25, still present | V7: Runtime re-confirm in progress on isolated stack (2026-10-20) | W7: node verify/run.mjs --only WC-035
A8: WC-038 | B8: Opening the invoice screen attempts to create a tax invoice, with no user action | C8: S2 Critical | D8: P1 | E8: Skilling Manager, Skilling Partner | F8: no screen reaches this; see Steps | G8: Transactional integrity | H8: Phase 1 | I8: UAT / dev (read-only) | J8: 1. Sign in as Skilling Partner. 2. Call /sp/invoicing/view-batch-invoice/prepare-invoice/:batchId/:installment/:centerName and the equivalent /sm/invoicing-management/... route once and note the resulting record. 3. Call it again with exactly the same payload. 4. Check whether a second record or a second effect appeared. | K8: Repeating the same call does not repeat its effect. | L8: navigation changes state. A GET-style page visit triggers a write against a finance workflow, which means: - refreshing, bookmarking, sharing the link or pressing back re-fires invoice preparation; - any user who merely *opens* the screen to look at it performs a financial action; - the operation is not idempotent by URL, so duplicate or incorrect invoices are plausible. | M8: on page load, with no interaction whatsoever, the application issues POST .../youth_skilling.api.invoice.prepare_tax_invoice?batch_id=<batch>&installment=1&center=<centre>. Reproduced on both the Skilling Partner and Skilling Manager applications. | N8: evidence/idempotency-results.json · suite/probes/idempotency-probe.mjs · re-check: node verify/run.mjs --only WC-038 · findings/findings-log.md -> WC-038 | O8: the screen should load its data with a GET and perform invoice preparation only on explicit user confirmation. | P8: Verified | R8: Open | U8: Open — re-checked 2026-09-25, still present | V8: Open — awaiting fix | W8: node verify/run.mjs --only WC-038
A9: WC-043 | B9: Blank routes are crashing on null navigation state | C9: S2 Critical | D9: P1 | E9: Facilitator and Counsellor | F9: no screen reaches this; see Steps | G9: Error handling | H9: Phase 1 | I9: UAT / dev (read-only) | J9: 1. Sign in as Facilitator and Counsellor. 2. Paste /fc/badge-table into the address bar and load it directly, rather than navigating to it inside the app. 3. The screen renders blank. Open the browser console and read the exception, which names the property read from a null navigation state. 4. Repeat from inside the app by clicking through to the same screen; it renders. | K9: A 4xx response with a message the caller can act on. No stack trace and no HTTP 500. | L9: See the register entry for impact. | M9: the full sweep captures uncaught JavaScript exceptions. Five routes throw:; Persona; Route; Exception; FC; /fc/badge-table; Cannot read properties of null (reading 'viewType'); FC; /fc/batch-management/view-batch; Cannot read properties of null (reading 'batchId'); FC; /fc/view-post-test; Cannot read properties of null (reading 'batch_id'); FC; /fc/group-based-counselling/attendance; Cannot read properties of null (reading 'length'); SYC; /group-based-counselling/attendance; Cannot read properties of null (reading 'length') | N9: test-results-run1/sweep-route-sweep--fc-rout-c69cf--fc-badge-table-BadgeTable--fc-retry1/test-failed-1.png · test-results-run1/sweep-route-sweep--fc-rout-4948a-ement-view-batch-ViewBatch--fc/test-failed-1.png · test-results-run1/sweep-route-sweep--fc-rout-857ce-iew-post-test-ViewPostTest--fc/test-fa · evidence/validation-probe-results.json · suite/probes/validation-probe.mjs … (full detail in the findings register) | O9: read identifiers from URL parameters rather than router state, and guard the state access (location.state?.batchId). The identifier is already in the URL for the :batchId routes, so the data needed is present. It is simply not being read from there. | P9: Verified — root cause, corrects an earlier classification | R9: Open | U9: Open — re-checked 2026-09-25, still present | V9: Open — awaiting fix | W9: node verify/run.mjs --only WC-043
A10: WC-068 | B10: The complete API specification is published to unauthenticated callers | C10: S2 Critical | D10: P1 | E10: no account required (unauthenticated) | F10: no screen reaches this; see Steps | G10: Authorisation | H10: Phase 2 | I10: UAT / dev (read-only) | J10: 1. Sign in as an authenticated staff account — any authenticated account is enough. 2. Call youth_skilling.api.docs.swagger_spec with no special privileges. 3. Observe that the call is accepted rather than refused, and check whether anything changed. | K10: The endpoint checks the caller's authorisation before acting, and refuses the call when the caller is not permitted. | L10: See the register entry for impact. | M10: GET {BACKEND}/api/method/youth_skilling.api.docs.swagger_spec with no Authorization header returns HTTP 200 and the full specification. | N10: evidence/gate-probe-results.json · evidence/bypass-endpoints.json · suite/probes/gate-probe.mjs · re-check: node verify/run.mjs --only WC-068 · findings/findings-log.md -> WC-068 | O10: remove allow_guest=True from the three swagger_spec functions. The specifications remain available to authenticated staff, which is presumably the intent. This is a one-word change in three places. | P10: Verified | R10: Open | U10: Open — re-checked 2026-09-25, still present | V10: Partially fixed — youth_skilling specs now require auth; batch_management swagger_spec still public | W10: node verify/run.mjs --only WC-068
A11: WC-073 | B11: The platform's permission design forces over-privileged accounts or bypasses permissions entirely | C11: S2 Critical | D11: P1 | E11: Outreach Coordinator, Centre Head, Facilitator and Counsellor, Skilling Partner | F11: /oc/tasks, /ch/ch-tasks, /ch/individual-target, /ch/staff-monitoring, /fc/tasks, /sp/tasks | G11: Authorisation | H11: Phase 2 | I11: UAT / dev (read-only) | J11: 1. Sign in as an authenticated staff account — any authenticated account is enough. 2. Call outreach.apis.task.task.create_task with no special privileges. 3. Observe that the call is accepted rather than refused, and check whether anything changed. | K11: The endpoint checks the caller's authorisation before acting, and refuses the call when the caller is not permitted. | L11: See the register entry for impact. | M11: Fact; Value; WeConnect doctypes; 293; granting only System Manager; 178; granting no role at all; 115; granting any other role; 0; API endpoints passing ignore_permissions=True; 296 of 866. | N11: evidence/gate-probe-results.json · evidence/bypass-endpoints.json · suite/probes/gate-probe.mjs · re-check: node verify/run.mjs --only WC-073 · findings/findings-log.md -> WC-073 | O11: define roles per persona with appropriate doctype permissions and assign them through role profiles, so authorisation is a property of the framework rather than of whether each endpoint remembered to check. | P11: Verified | R11: Open | U11: Open — re-checked 2026-09-25, still present | V11: Partially fixed — accounts no longer hold System Manager (live); source ignore_permissions bypass unchanged | W11: node verify/run.mjs --only WC-073
A12: WC-077 | B12: An unauthenticated endpoint attempts to provision a System Manager account | C12: S2 Critical | D12: P1 | E12: no account required (unauthenticated) | F12: no screen reaches this; see Steps | G12: Authorisation | H12: Phase 2 | I12: UAT / dev (read-only) | J12: 1. Sign in as an authenticated staff account — any authenticated account is enough. 2. Call weconnect-backend-authentication, authentication/api/registration.py, create_user(email, first_name, last_name), decorated @frappe.whitelist(methods=["POST"], allow_guest=True) with no special privileges. 3. Observe that the call is accepted rather than refused, and check whether anything changed. | K12: The endpoint checks the caller's authorisation before acting, and refuses the call when the caller is not permitted. | L12: See the register entry for impact. | M12: An unauthenticated endpoint attempts to provision a System Manager account. | N12: evidence/gate-probe-results.json · evidence/bypass-endpoints.json · suite/probes/gate-probe.mjs · re-check: node verify/run.mjs --only WC-077 · findings/findings-log.md -> WC-077 | O12: (1) require an authenticated caller with an appropriate role — remove allow_guest=True; (2) do not grant System Manager on self-service creation — assign the least-privilege role the account needs; (3) if open registration is intended, separate "request an account" from "grant roles" so the two are never the same call. | P12: Verified — runtime blocks it | R12: Open | U12: Open — re-checked 2026-09-25, still present | V12: Open — awaiting fix | W12: node verify/run.mjs --only WC-077
A13: WC-078 | B13: Any authenticated user can delete any file by URL (no ownership check) | C13: S2 Critical | D13: P1 | E13: any authenticated account | F13: no screen reaches this; see Steps | G13: Authorisation | H13: Phase 2 | I13: Isolated stack (synthetic data) | J13: 1. Sign in as Skilling Partner — any authenticated account is enough. 2. Call weconnect-backend-outreach, outreach/apis/registration/files.py, delete_file_by_url(), @frappe.whitelist(methods=["POST"]) with no special privileges. 3. Observe that the call is accepted rather than refused, and check whether anything changed. | K13: The endpoint checks the caller's authorisation before acting, and refuses the call when the caller is not permitted. | L13: Registration documents on this platform include uploaded identity and eligibility paperwork for youth. Any authenticated user — any of the six personas, and per the permission-design finding possibly every staff account — can permanently delete any such file from both S3 and the database by supplying its URL, with no audit of authorisation because none occurs. Deletion is irreversible. | M13: Registration documents on this platform include uploaded identity and eligibility paperwork for youth. Any authenticated user — any of the six personas, and per the permission-design finding possibly every staff account — can permanently delete any such file from both S3 and the database by supplying its URL, with no audit of authorisation because none occurs. Deletion is irreversible. | N13: evidence/gate-probe-results.json · evidence/bypass-endpoints.json · suite/probes/gate-probe.mjs · re-check: node verify/run.mjs --only WC-078 · findings/findings-log.md -> WC-078 | O13: verify the caller owns or has permission for the file's parent document before deleting; scope the lookup to files the caller may access; and log the deletion with the actor. | P13: Verified — runtime | R13: Open | U13: Open — re-checked 2026-09-25, still present | V13: Runtime re-confirm in progress on isolated stack (2026-10-20) | W13: node verify/run.mjs --only WC-078
A14: WC-079 | B14: Systemic: mutating endpoints bypass permissions with no authorization check | C14: S2 Critical | D14: P1 | E14: Centre Head, Skilling Partner | F14: no screen reaches this; see Steps | G14: Authorisation | H14: Phase 2 | I14: Source review | J14: 1. Sign in as Centre Head — any authenticated account is enough. 2. Call the 296 ignore_permissions=True sites across 68 files (evidence/bypass-endpoints.json) with no special privileges. 3. Observe that the call is accepted rather than refused, and check whether anything changed. | K14: The endpoint checks the caller's authorisation before acting, and refuses the call when the caller is not permitted. | L14: See the register entry for impact. | M14: Of 214 mutating endpoints, 39 bypass permissions and contain no authorization check of any kind. Of those, 35 also perform a direct write — they are not merely unguarded reads mislabelled, they change data. The remaining 4 route through an approval or do not write. | N14: data/authz-audit.json · data/gate-probe-results.json · data/state-boundary-results.json · data/truly-bypassed-endpoints.json · evidence/gate-probe-results.json · evidence/bypass-endpoints.json · suite/probes/gate-probe.mjs · re-check: node verify/run.mjs --only WC-079 · findings/findings-log.md -> WC-079 | O14: authorization should be enforced centrally. A decorator or a base handler that every mutating endpoint passes through — rather than reimplemented (or forgotten) per endpoint. The current design guarantees this class of defect recurs with every new endpoint. This is the same root cause named in the permission-design finding. | P14: Verified — source + 36/36 confirmed at runtime | R14: Open | U14: Open — re-checked 2026-09-25, still present | V14: Still present — 322 ignore_permissions sites (up from ~296) | W14: node verify/run.mjs --only WC-079
A15: WC-085 | B15: Financial endpoints share the confirmed cross-centre write gap | C15: S2 Critical | D15: P1 | E15: All personas / not role-specific | F15: no screen reaches this; see Steps | G15: Authorisation | H15: Phase 2 | I15: Source review | J15: 1. Sign in as an authenticated staff account and take the API credential from the login response. 2. Identify a record owned by a centre this account is not permitted for. 3. Call youth_skilling.api.invoice.raise_invoice(invoice_id, batch_id, center, installment, ...) against that record. 4. Read the response, then read the record back from the database — the response alone is not proof. | K15: The call is refused for a centre the account has no permission over. No record is returned and no record is changed. | L15: See the register entry for impact. | M15: Financial endpoints share the confirmed cross-centre write gap. | N15: evidence/state-boundary-results.json · suite/probes/rbac-write-probe.mjs · re-check: node verify/run.mjs --only WC-085 · findings/findings-log.md -> WC-085 | O15: derive center from the caller's permitted scope rather than accepting it as a parameter, and remove ignore_permissions=True. Same pattern as the close_batch fix. | P15: Verified — source; runtime blocked by fixture | R15: Open | U15: Open — re-checked 2026-09-25, still present | V15: Runtime re-confirm in progress on isolated stack (2026-10-20) | W15: node verify/run.mjs --only WC-085
A16: WC-088 | B16: Enquiry Form status change is completely broken by a variable typo | C16: S2 Critical | D16: P1 | E16: All personas / not role-specific | F16: no screen reaches this; see Steps | G16: Error handling | H16: Phase 2 | I16: UAT / dev (read-only) | J16: 1. Sign in as an account permitted for the Enquiry Form screen. 2. Change the status of any Enquiry Form through the API, with a valid payload. 3. The call returns HTTP 500 UnboundLocalError. It fails on every call, not only on malformed input, because the handler reads a variable that was never assigned. 4. The same defect is present at two sites: outreach/apis/enquiry_form/form.py:38 and outreach/apis/enquiry.py:248. | K16: A 4xx response with a message the caller can act on. No stack trace and no HTTP 500. | L16: A core Outreach flow is non-functional. An enquiry cannot be marked dropped-off or standby through this endpoint. The frontend may call a different path, but this whitelisted endpoint — documented in the public API spec — is dead. | M16: A valid Enquiry Form was created and its status change attempted through the API; the endpoint returned HTTP 500 UnboundLocalError. Confirmed against source. | N16: evidence/validation-probe-results.json · suite/probes/validation-probe.mjs · re-check: node verify/run.mjs --only WC-088 · findings/findings-log.md -> WC-088 | O16: ids = json.loads(ids). A one-word correction, and a test that calls the endpoint would have caught it — which is the point of this phase. | P16: Verified — runtime | Q16: 2026-09-22 | R16: Open | U16: Open — re-checked 2026-09-25, still present | V16: Still present — id=json.loads(id) typo at both sites | W16: node verify/run.mjs --only WC-088
A17: WC-105 | B17: Systemic: data scoping is disabled for System Manager in application code, at 45 sites, while the platform forces that role onto every staff account | C17: S2 Critical | D17: P1 | E17: All personas / not role-specific | F17: no screen reaches this; see Steps | G17: Authorisation | H17: Phase 2 | I17: UAT / dev (read-only) | J17: 1. Sign in as an authenticated staff account and take the API credential from the login response. 2. Identify a record owned by a centre this account is not permitted for. 3. Call the 45 scoping sites across 26 files (evidence/authz-audit.json) against that record. 4. Read the response, then read the record back from the database — the response alone is not proof. | K17: The call is refused for a centre the account has no permission over. No record is returned and no record is changed. | L17: See the register entry for impact. | M17: The Outreach Coordinator credential reports permitted_centres = ["Kukatpally", "Bhawani Peth"], yet GET /api/resource/Role Profile and GET /api/resource/User both return 200 — reads only a System Manager obtains. That elevation is what produced the counselling S1: 10 of 10 youth counselling records returned from centres the account has no permission for. | N17: evidence/state-boundary-results.json · suite/probes/rbac-write-probe.mjs · re-check: node verify/run.mjs --only WC-105 · findings/findings-log.md -> WC-105 | O17: 1. Remove the role check from data-scoping paths. Scoping should not be conditional on a role. Where a genuine administrative override is needed, make it explicit, narrow and audited — not a blanket pass on youth records. 2. Remove the need for the role, by giving each persona role real doctype permissions. Until that lands, fixing (1) alone will lock staff out, so the two must ship together. 3. Add a test asserting that a non-administrative account cannot read a record outside its permitted centres, for each list endpoint. | P17: Verified — source, 45 sites; one instance confirmed exploited on the live platform, runtime read-only | R17: Open | U17: Open — re-checked 2026-09-25, still present | V17: Still present — 66 System Manager references in backend code | W17: node verify/run.mjs --only WC-105
A18: WC-115 | B18: Any authenticated account, including an external partner, can trigger a bulk export of programme data to an external Google Sheet | C18: S2 Critical | D18: P1 | E18: any authenticated account, including an external partner | F18: no screen reaches this; see Steps | G18: Authorisation | H18: Phase 2 (security) | I18: Isolated stack (synthetic data) | J18: 1. Sign in as Facilitator and Counsellor — any authenticated account is enough. 2. Call outreach.apis.lcf_mastersheet_sync.sync_to_lcf_mastersheet with no special privileges. 3. Observe that the call is accepted rather than refused, and check whether anything changed. | K18: The endpoint checks the caller's authorisation before acting, and refuses the call when the caller is not permitted. | L18: See the register entry for impact. | M18: Called on the isolated instance as sp — the Skilling Partner persona, which represents an external training provider and is the lowest-trust account in the system — the endpoint returned HTTP 200 and reached its own logic, failing only with "LCF Google Sheet ID is not set in Google Integration Settings." That failure is downstream of where a permission check belongs. The same result for fc. No caller was refused. | N18: evidence/gate-probe-results.json · evidence/bypass-endpoints.json · suite/probes/gate-probe.mjs · re-check: node verify/run.mjs --only WC-115 · findings/findings-log.md -> WC-115 | O18: require an explicit role for this endpoint — it is an administrative reporting function, not a per-persona one — and log every invocation with the calling account. It is a strong candidate for the central authorisation change recommended for the mutating endpoints, since it is exactly the class of sensitive operation that change is meant to cover. | P18: Verified — runtime, isolated instance | R18: Open | U18: Open — re-checked 2026-09-25, still present | V18: Runtime re-confirm in progress on isolated stack (2026-10-20) | W18: node verify/run.mjs --only WC-115
A19: WC-131 | B19: The password-reset OTP is a four-digit number with a short expiry, drawn with a non-cryptographic generator | C19: S2 Critical | D19: P1 | E19: any account (reset is by email, unauthenticated) | F19: no screen reaches this; see Steps | G19: Authentication / session | H19: Phase 2 (security) | I19: Source review | J19: 1. Open authentication/api/password.py, function generate_otp(). 2. Confirm it returns random.randint(1111, 9999) — four digits, non-cryptographic generator. 3. In verify_otp (same file), confirm there is no attempt counter or lockout on mismatch. 4. In password_reset_otp.py, confirm the expiry is three minutes. | K19: A reset code is drawn with a cryptographic generator, is long enough to resist guessing, and verification is attempt-limited. | L19: reset_password is unauthenticated, the OTP that gates it is weak, and verification is unthrottled — the conditions for account takeover by email address. Because every staff account holds System Manager (WC-073), compromising any account equals full administrative access. Candidate for S1; held at S2 only because the weakness is source-verified and a live takeover was deliberately not performed. Treat remediation with S1 urgency. | M19: generate_otp() returns random.randint(1111, 9999). verify_otp has no attempt limit. Expiry is 3 minutes. reset_password is allow_guest=True. | N19: source: authentication/api/password.py · findings/findings-log.md -> WC-131 | O19: Generate the code with the secrets module (e.g. a six-digit secrets.randbelow(900000)+100000), store an attempt counter on the Password Reset OTP record, and invalidate after a few failed verifications — the discipline the login path (WC-117) already applies. Keep the three-minute expiry. | P19: Verified — source | Q19: 2026-10-06 | R19: Open | U19: Open | V19: Partially fixed — OTP now CSPRNG (secrets.randbelow); still 4-digit
A20: WC-002 | B20: Target Data API returns 404 | C20: S2 Critical | D20: P2 | E20: Centre Head, Facilitator and Counsellor | F20: /ch/, /fc/, /fc/all-batches | G20: API contract | H20: Phase 1 | I20: UAT / dev (read-only) | J20: 1. Sign in as an authenticated staff account and open centre_head.api.target.main_dashboard.main_target (the Target Data widget's API) with the browser network tab open. 2. Find the failing request in the network log. 3. Note its URL and status code. | K20: The endpoint the screen calls exists on the deployed build and returns its data. | L20: See the register entry for impact. | M20: 404; widget shows "Data not available.". | N20: evidence/write-surface-classified.json · findings/findings-log.md -> WC-002 | O20: the widget calls an endpoint that is not present on the deployed build. Either restore centre_head.api.target.main_dashboard.main_target or remove the card that calls it. Either way the frontend should render an explicit empty state rather than the literal string shown today; the broken wording is tracked separately as S4. | P20: Verified — observed at first contact | R20: Open | U20: Open | V20: Open — awaiting fix
A21: WC-011 | B21: Client-side auth guard is hardcoded to true (disabled) | C21: S2 Critical | D21: P2 | E21: Facilitator and Counsellor, any persona (login) | F21: no screen reaches this; see Steps | G21: Authorisation | H21: Phase 1 | I21: UAT / dev (read-only) | J21: 1. Sign in as Facilitator and Counsellor — any authenticated account is enough. 2. Call /fc/all-batches with no special privileges. 3. Observe that the call is accepted rather than refused, and check whether anything changed. | K21: The endpoint checks the caller's authorisation before acting, and refuses the call when the caller is not permitted. | L21: the FC frontend renders all authenticated routes regardless of login state. Real severity depends on whether the backend rejects requests lacking a valid session token: - If backend enforces auth -> attacker sees an empty shell (S2, still ships broken security posture). - If backend does not -> unauthenticated data exposure (S1). | M21: const isAuthenticated = true; — the route guard never reads auth state. The redirect-to-login branch is dead code. URLs.Login isn't even defined in routes.js (would ReferenceError if that branch ever ran). | N21: test-results-run2/sweep-route-sweep--fc-rout-8f432--fc-all-batches-AllBatches--fc/test-failed-1.png · evidence/gate-probe-results.json · evidence/bypass-endpoints.json · suite/probes/gate-probe.mjs · findings/findings-log.md -> WC-011 | O21: See register. | P21: Verified | Q21: 2026-09-18 | R21: Open | U21: Open | V21: Fixed (retest 2026-10-20) — auth guard now derived from credentials, not hardcoded true
A22: WC-013 | B22: Long-lived API secret stored in localStorage | C22: S2 Critical | D22: P2 | E22: any persona (login) | F22: no screen reaches this; see Steps | G22: Security configuration | H22: Phase 1 | I22: UAT / dev (read-only) | J22: 1. No sign-in needed for the header checks. 2. Issue the request described in the Actual Result column against the deployed host. 3. Inspect the response headers (or the cookie attributes) rather than the body. 4. Fastest route: node verify/run.mjs --only WC-013 | K22: The protective setting is in place and the unsafe request is refused. | L22: Frappe API key/secret are long-lived credentials (not short session tokens). Any XSS on the domain exfiltrates a permanent API credential -> persistent account takeover. httpOnly cookie would mitigate. | M22: login stores Frappe api_key/api_secret in localStorage; every request sends Authorization: token <key>:<secret>. | N22: verify/run.mjs · findings/findings-log.md -> WC-013 | O22: move the session to a short-lived, httpOnly, Secure, SameSite cookie so it cannot be read from JavaScript, and shorten its lifetime. A token in localStorage is readable by any script on the origin — and the persona applications share a single origin, so an XSS in any one of them yields a credential valid for the others. | P22: Verified | R22: Open | U22: Open | V22: Still present — api_secret still written to localStorage (15 sites)
A23: WC-016 | B23: 14 routes render blank on direct load | C23: S2 Critical | D23: P2 | E23: Facilitator and Counsellor, Skilling Partner, Skilling Youth Coordinator | F23: no screen reaches this; see Steps | G23: Frontend | H23: Phase 1 | I23: UAT / dev (read-only) | J23: 1. Sign in as Facilitator and Counsellor. 2. Paste /syc/coming-soon into the address bar and load it directly — do not navigate to it from inside the app. 3. Observe whether the screen renders. Open the browser console and note any exception. | K23: The screen renders its content when the URL is opened directly, refreshed, or reached from a bookmark. | L23: See the register entry for impact. | M23: the full suite executed three consecutive times. Each route below rendered nothing in every execution, so environmental flake is excluded — routes failing in only some executions are classified separately and are not listed here. Body renders 0 characters. | N23: test-results-run1/sweep-route-sweep--fc-rout-857ce-iew-post-test-ViewPostTest--fc/test-failed-1.png · test-results-run1/sweep-route-sweep--fc-rout-7d3d1-dance-GroupBasedAttendance--fc-retry1/test-failed-1.png · test-results-run1/sweep-route-sweep--fc-rout-c69cf--fc-badge-table-BadgeTable--fc-retry1/ · findings/findings-log.md -> WC-016 | O23: root-caused separately to a null navigation state. These routes read their identifier from React Router state, which is absent on a direct load or a refresh. Read the identifier from URL parameters and guard the read. One fix closes this and the group-based route failures below. | P23: Verified — three consecutive executions, 2026-09-19 | Q23: 2026-09-19 | R23: Open | U23: Open | V23: Open — awaiting fix
A24: WC-017 | B24: Two "group-based" routes fail identically in both FC and SYC | C24: S2 Critical | D24: P2 | E24: All personas / not role-specific | F24: no screen reaches this; see Steps | G24: Frontend | H24: Phase 1 | I24: UAT / dev (read-only) | J24: 1. Sign in as an authenticated staff account. 2. Paste /fc/group-based-counselling/attendance and the equivalent /syc/ route into the address bar and load it directly — do not navigate to it from inside the app. 3. Observe whether the screen renders. Open the browser console and note any exception. | K24: The screen renders its content when the URL is opened directly, refreshed, or reached from a bookmark. | L24: two independent apps failing on the same two route names points at a shared component (persona-common-components) or a shared route-state contract, not at two coincidental per-app bugs. One fix likely clears four failures. | M24: two independent apps failing on the same two route names points at a shared component (persona-common-components) or a shared route-state contract, not at two coincidental per-app bugs. One fix likely clears four failures. | N24: findings/findings-log.md -> WC-017 | O24: the same null navigation state as the 14 blank routes — identical cause, identical remedy. Read identifiers from URL parameters rather than router state. | P24: Verified — new | R24: Open | U24: Open | V24: Open — awaiting fix
A25: WC-018 | B25: SYC /curriculum data API returns 500 | C25: S2 Critical | D25: P2 | E25: Skilling Manager, Skilling Partner, Skilling Youth Coordinator | F25: /sm/assessments, /sm/assignments, /sm/curriculum, /sp/assignment, /sp/curriculum, /syc/asses | G25: Error handling | H25: Phase 1 | I25: Isolated stack (synthetic data) | J25: 1. Sign in as Skilling Youth Coordinator. 2. Open the curriculum screen, or call youth_skilling.api.curriculum.curriculum_list directly with valid arguments. 3. Read the HTTP status. The call fails on a correctly formed request, not only on a malformed one. | K25: A 4xx response with a message the caller can act on. No stack trace and no HTTP 500. | L25: See the register entry for impact. | M25: page shell renders (~140 chars) but a backend data call returns HTTP 500. | N25: evidence/validation-probe-results.json · suite/probes/validation-probe.mjs · findings/findings-log.md -> WC-018 | O25: Verified on the isolated instance (2026-09-20): youth_skilling.api.curriculum.curriculum_list returns HTTP 500 with TypeError: curriculum_list() missing 1 required positional argument: 'skilling_batch_id', and the response carries a traceback. This is therefore an instance of the missing-argument crash pattern rather than a separate defect: give the parameter a default, validate presence explicitly and return 400 naming the missing field. Note the sibling batch_management.api.curriculum.list answers 417 to the same shape of call. The two disagree on how a bad request should be rejected. | P25: Verified | Q25: 2026-09-20 | R25: Open | U25: Open | V25: Open — awaiting fix
A26: WC-020 | B26: Backend returns 500s under modest concurrency | C26: S2 Critical | D26: P2 | E26: Facilitator and Counsellor, Skilling Partner, Skilling Youth Coordinator | F26: no screen reaches this; see Steps | G26: Performance | H26: Phase 1 | I26: UAT / dev (read-only) | J26: 1. Drive /fc/family-counselling with several sessions at once, increasing concurrency step by step. 2. Record the HTTP status and response time at each level. 3. Note the point at which results stop being consistent. | K26: The endpoint responds within the expected load without degrading, and large result sets are paginated. | L26: See the register entry for impact. | M26: at 6 parallel workers many data endpoints returned 500; at ≤3 workers / serialized they return 200. Backend stability/scaling concern. Recommend a dedicated load test. | N26: test-results/sweep-route-sweep--fc-rout-d40b6-fc-counselling-Counselling--fc/test-failed-1.png · evidence/gate-probe-results.json · findings/findings-log.md -> WC-020 | O26: size the worker pool for the expected concurrency, and return 503 with a retry hint when saturated rather than 500 with a traceback. A 500 tells a client its request was wrong; a 503 tells it to retry, which is the truthful answer under load. | P26: Verified | Q26: 2026-09-18 | R26: Open | U26: Open | V26: Open — awaiting fix
A27: WC-027 | B27: Systematic WCAG critical violations, concentrated in shared navigation | C27: S2 Critical | D27: P2 | E27: All personas / not role-specific | F27: no screen reaches this; see Steps | G27: Accessibility | H27: Phase 1 | I27: UAT / dev (read-only) | J27: 1. Load the shared sidebar navigation component, which appears on every route as an authenticated staff account. 2. Run axe-core against the page (or any WCAG 2.1 AA checker). 3. Read the violations for the element named in the Actual Result column. | K27: The element meets WCAG 2.1 AA. | L27: a screen-reader user cannot identify navigation items (no alt text), cannot operate icon-only buttons (no accessible name), and meets a malformed list structure on every page. In practice the platform is not usable without sight. For a foundation delivering public-benefit programmes this is also a procurement and funding exposure, not only a usability one. | M27: The distribution matters as much as the count. Four rules fire on every route scanned, in every persona. This is not 23 pages each carrying its own mistakes. It is one shared layout and navigation component, repeated across all of them. The 181 orphaned <li> elements and the unlabelled icon images match the sidebar navigation observed during route mapping. Impact: a screen-reader user cannot identify navigation items (no alt text), cannot operate icon-only buttons (no accessible name), and meets a malformed list structure on every page. | N27: the axe-core run across all 235 routes · findings/findings-log.md -> WC-027 | O27: correct the sidebar list markup (<li> inside <ul>), add alt to nav icons, give icon-only buttons an aria-label, and remove ARIA attributes not permitted on their roles — all in the shared navigation component. | P27: Verified | R27: Open | U27: Open | V27: Open — awaiting fix
A28: WC-047 | B28: Backend concurrency sensitivity, quantified | C28: S2 Critical | D28: P2 | E28: All personas / not role-specific | F28: no screen reaches this; see Steps | G28: Performance | H28: Phase 1 | I28: UAT / dev (read-only) | J28: 1. Drive the backend, driven at 3 then 5 concurrent sessions with several sessions at once, increasing concurrency step by step. 2. Record the HTTP status and response time at each level. 3. Note the point at which results stop being consistent. | K28: The endpoint responds within the expected load without degrading, and large result sets are paginated. | L28: five simultaneous users is not a load test. It is five members of staff working at the same moment, which any centre would exceed on a normal morning. The measured behaviour at that level is pages failing to render. | M28: Method: the identical 235-route sweep executed twice, differing only in the number of simultaneous sessions. Same routes, same assertions, same build, minutes apart. - Note on the two instability figures in this register: this table reports a controlled comparison of two single executions (3.4% at three sessions, 6.8% at five). The 3.0% quoted elsewhere is the rate across three consecutive executions at three sessions, which is the more reliable figure and the one used in the client documents. Both describe the platform; they differ in sample size. | N28: evidence/gate-probe-results.json · findings/findings-log.md -> WC-047 | O28: as for the finding above. Capacity is a deployment parameter rather than a code defect, but the failure *mode* is a defect: saturation should surface as 503, not 500 with a traceback. Size the pool against the measured dose-response and re-measure after any change to worker count. | P28: Verified — dose-response | R28: Open | U28: Open | V28: Open — awaiting fix
A29: WC-058 | B29: An installed application is absent from the repositories handed over | C29: S2 Critical | D29: P2 | E29: All personas / not role-specific | F29: no screen reaches this; see Steps | G29: Handover / configuration | H29: Phase 2 | I29: Source review | J29: Inspection, not a runtime reproduction. 1. Open frappe.utils.change_log.get_versions. 2. Confirm what the Actual Result column describes is present (or absent). 3. Full reasoning is in findings/findings-log.md under WC-058. | K29: Everything needed to build and run the platform is present in the repositories the foundation owns. | L29: The platform as deployed cannot be rebuilt from the code the foundation owns. One installed component would be unavailable in a disaster recovery, a change of supplier, or a new environment build. The gap is one application rather than three, but the governance question is unchanged in kind. | M29: frappe.utils.change_log.get_versions, which enumerates the applications installed on the site, reports twelve:; Source; Applications; Obtainable; Framework; frappe 15.113.2 · erpnext 15.114.0 · insights 3.12.5; Yes — open source; WeConnect; the eight supplied backends; Yes; Vendor; fintoo_analytics_bridge; No fintoo_analytics_bridge exists in no repository in the foundation's GitHub organisation. The organisation holds eighteen repositories; none corresponds to it. It appears to belong to the development vendor. | N29: evidence/doctype-schemas.json · suite/probes/compare-environments.mjs · findings/findings-log.md -> WC-058 | O29: (1) establish who owns fintoo_analytics_bridge and obtain either the source or a written escrow undertaking. The platform cannot be rebuilt or fully audited without it; (2) declare required_apps in each app's hooks.py so the deployable set is recorded in code; (3) remove the orphaned Module Def records for apps that are not installed (hrms, mannlowe_support, materialized_view_builder), so the installed-application list stops disagreeing with itself. | P29: Verified — corrected 2026-09-20 | Q29: 2026-09-20 | R29: Open | U29: Open | V29: Open — awaiting fix
A30: WC-069 | B30: The permission model exists in no repository | C30: S2 Critical | D30: P2 | E30: All personas / not role-specific | F30: no screen reaches this; see Steps | G30: Handover / configuration | H30: Phase 2 | I30: Isolated stack (synthetic data) | J30: Inspection, not a runtime reproduction. 1. Open the Role Profile and DocPerm records — absent from all eighteen repositories. 2. Confirm what the Actual Result column describes is present (or absent). 3. Full reasoning is in findings/findings-log.md under WC-069. | K30: Everything needed to build and run the platform is present in the repositories the foundation owns. | L30: See the register entry for impact. | M30: of 297 doctype definitions across the eight applications, 182 carry permission rules and every one of them grants a single role: System Manager. The remaining 115 carry no permission rules at all. Not one doctype grants any WeConnect role. - No application defines a Role or Role Profile record. The declared fixtures export only Custom Field and Property Setter. - Yet the code refers to these roles 227 times — "Skilling Partner" alone appears 174 times. | N30: evidence/doctype-schemas.json · suite/probes/compare-environments.mjs · findings/findings-log.md -> WC-069 | O30: export the roles, role profiles and permission rules as app fixtures so they are versioned with the code that depends on them. | P30: Verified | R30: Open | U30: Open | V30: Open — awaiting fix
A31: WC-087 | B31: Runtime configuration required to operate the platform is not in the repositories | C31: S2 Critical | D31: P2 | E31: All personas / not role-specific | F31: no screen reaches this; see Steps | G31: Handover / configuration | H31: Phase 2 | I31: UAT / dev (read-only) | J31: Inspection, not a runtime reproduction. 1. Open sites/common_site_config.json and the per-site site_config.json. 2. Confirm what the Actual Result column describes is present (or absent). 3. Full reasoning is in findings/findings-log.md under WC-087. | K31: Everything needed to build and run the platform is present in the repositories the foundation owns. | L31: This is the same class as the missing permission model and the missing vendor application: the foundation cannot rebuild a working platform from the code it owns. A disaster recovery would produce a system that installs cleanly and then fails the moment anyone tries to register a youth, with errors that name framework internals rather than the missing setup. The configuration — naming series, master data, roles, permissions — exists only as production database rows, unversioned and unreviewed. | M31: A pattern, now seen three times. Standing up the platform from its repositories produces a system that cannot perform its core flows until configuration that lives only in the production database is recreated by hand. Concretely, on a clean install: - Demonstrated, not asserted. create_pre_enquiry — a core Outreach Coordinator flow — returned HTTP 400 "Naming Series mandatory" on a clean install, because create_youth does not set a series and none is configured by default. Setting the series made the flow succeed. The stage and status failures were identical. | N31: evidence/doctype-schemas.json · suite/probes/compare-environments.mjs · findings/findings-log.md -> WC-087 | O31: ship this configuration as fixtures (Frappe's mechanism for exactly this) or as an install/after_migrate patch, so a fresh install is a working install. Some patches exist (placement status master data). The pattern should be extended to the naming series, stages, statuses, roles and role profiles the core flows require. | P31: Verified | R31: Open | U31: Open | V31: Open — awaiting fix
A32: WC-091 | B32: Application code gates on roles that do not exist on a fresh install | C32: S2 Critical | D32: P2 | E32: All personas / not role-specific | F32: no screen reaches this; see Steps | G32: Handover / configuration | H32: Phase 2 | I32: UAT / dev (read-only) | J32: Inspection, not a runtime reproduction. 1. Open frappe.db.exists("Role", "Skilling Partner"). 2. Confirm what the Actual Result column describes is present (or absent). 3. Full reasoning is in findings/findings-log.md under WC-091. | K32: Everything needed to build and run the platform is present in the repositories the foundation owns. | L32: See the register entry for impact. | M32: across the skilling application alone, endpoint logic branches on membership in named roles — "Skilling Partner" in user_roles (7×), "Skilling Manager" in user_roles (5×), "Center Head" in roles, "System Manager" and others. But on an instance built from the repositories, the persona roles do not exist: frappe.db.exists("Role", "Skilling Partner") is false, and no Role, Role Profile or role assignment for any persona is shipped in any app. | N32: evidence/doctype-schemas.json · suite/probes/compare-environments.mjs · findings/findings-log.md -> WC-091 | O32: ship the roles (and role profiles, and the permission rules that reference them) as fixtures, so a fresh install has the access-control model the code assumes. | P32: Verified | R32: Open | U32: Open | V32: Open — awaiting fix
